<?xml version="1.0"?>
<robot name="veggiebot" xmlns:xacro="http://ros.org/wiki/xacro">
  <xacro:include filename="$(find veggie_urdf)/urdf/common_properties.xacro"/>

  <link name="base_footprint"/>

  <joint name="base_joint" type="fixed">
    <parent link="base_footprint"/>
    <child link="base_link"/>
    <origin xyz="0 0 0.0375" rpy="0 0 0"/>
  </joint>

  <link name="base_link">
   <inertial>
      <mass value="1" />
      <origin xyz="0 0 0" />
      <inertia ixx="1.0" ixy="0.0" ixz="0.0"
        iyy="1.0" iyz="0.0" izz="1.0" />
   </inertial>
    <visual>
      <origin xyz="0 0 0.0" rpy="0 0 0"/>
      <geometry>
        <mesh filename="package://veggie_urdf/meshes/Visuals/base_link.stl"/>
      </geometry>
        <material name="orange"/>
    </visual>
   <collision>
      <origin xyz="0 0 0.0" rpy="0 0 0"/>
      <geometry>
        <mesh filename="package://veggie_urdf/meshes/Collisions/base_link.stl"/>
      </geometry>
    </collision>

  </link>

  <link name="second_link">
    <inertial>
      <mass value="0.1" />
      <origin xyz="0 0 0" />
      <inertia ixx="1.0" ixy="0.0" ixz="0.0"
        iyy="1.0" iyz="0.0" izz="1.0" />
   </inertial>
    <visual>
      <origin xyz="0 0 0.0" rpy="0 0 0"/>
      <geometry>
        <mesh filename="package://veggie_urdf/meshes/Visuals/second_level.stl"/>
      </geometry>
        <material name="black"/>
    </visual>
  <collision>
      <origin xyz="0 0 0.0" rpy="0 0 0"/>
      <geometry>
        <mesh filename="package://veggie_urdf/meshes/Collisions/second_level.stl"/>
      </geometry>
    </collision>
  </link>
  
  <joint name="fixed_joint_1" type="fixed">
    <parent link="base_link"/>
    <child link="second_link"/>
    <origin xyz="0 0 0" rpy="0 0 0"/>
   </joint>

  <link name="third_link">
    <inertial>
      <mass value="0.1" />
      <origin xyz="0 0 0" />
      <inertia ixx="1.0" ixy="0.0" ixz="0.0"
        iyy="1.0" iyz="0.0" izz="1.0" />
    </inertial>
    <visual>
      <origin xyz="0 0 0.0" rpy="0 0 0"/>
      <geometry>
        <mesh filename="package://veggie_urdf/meshes/Visuals/second_level_2.stl"/>
      </geometry>
        <material name="blue"/>
    </visual>
    <collision>
      <origin xyz="0 0 0.0" rpy="0 0 0"/>
      <geometry>
        <mesh filename="package://veggie_urdf/meshes/Collisions/second_level_2.stl"/>
      </geometry>
    </collision>
  </link>
 
  <joint name="fixed_joint_2" type="fixed">
    <parent link="second_link"/>
    <child link="third_link"/>
    <origin xyz="0 0 0" rpy="0 0 0"/>
   </joint>

  <link name="fourth_link">
    <inertial>
      <mass value="0.1" />
      <origin xyz="0 0 0" />
      <inertia ixx="1.0" ixy="0.0" ixz="0.0"
        iyy="1.0" iyz="0.0" izz="1.0" />
    </inertial>
    <visual>
      <origin xyz="0 0 0.0" rpy="0 0 0"/>
      <geometry>
        <mesh filename="package://veggie_urdf/meshes/Visuals/second_level_3.stl"/>
      </geometry>
        <material name="blue"/>
    </visual>
    <collision>
      <origin xyz="0 0 0.0" rpy="0 0 0"/>
      <geometry>
        <mesh filename="package://veggie_urdf/meshes/Collisions/second_level_3.stl"/>
      </geometry>
    </collision>
  </link>

  <joint name="fixed_joint_3" type="fixed">
    <parent link="third_link"/>
    <child link="fourth_link"/>
    <origin xyz="0 0 0" rpy="0 0 0"/>
   </joint>

  <link name="fifth_link">
      <inertial>
      <mass value="0.1" />
      <origin xyz="0 0 0" />
      <inertia ixx="1.0" ixy="0.0" ixz="0.0"
        iyy="1.0" iyz="0.0" izz="1.0" />
     </inertial>
      <visual>
      <origin xyz="0 0 0.0" rpy="0 0 0"/>
      <geometry>
        <mesh filename="package://veggie_urdf/meshes/Visuals/third_level_2.stl"/>
      </geometry>
        <material name="blue"/>
    </visual>
    <collision>
      <origin xyz="0 0 0.0" rpy="0 0 0"/>
      <geometry>
        <mesh filename="package://veggie_urdf/meshes/Collisions/third_level_2.stl"/>
      </geometry>
    </collision>
  </link>

 <joint name="fixed_joint_4" type="fixed">
    <parent link="fourth_link"/>
    <child link="fifth_link"/>
    <origin xyz="0 0 0" rpy="0 0 0"/>
   </joint>

 <link name="sixth_link">
    <inertial>
      <mass value="0.1" />
      <origin xyz="0 0 0" />
      <inertia ixx="1.0" ixy="0.0" ixz="0.0"
        iyy="1.0" iyz="0.0" izz="1.0" />
   </inertial>
    <visual>
      <origin xyz="0 0 0.0" rpy="0 0 0"/>
      <geometry>
        <mesh filename="package://veggie_urdf/meshes/Visuals/third_level.stl"/>
      </geometry>
        <material name="orange"/>
    </visual>
    <collision>
      <origin xyz="0 0 0.0" rpy="0 0 0"/>
      <geometry>
        <mesh filename="package://veggie_urdf/meshes/Collisions/third_level.stl"/>
      </geometry>
    </collision>
  </link>

 <joint name="fixed_joint_5" type="fixed">
    <parent link="fifth_link"/>
    <child link="sixth_link"/>
    <origin xyz="0 0 0" rpy="0 0 0"/>
   </joint>

<link name="battery">
    <inertial>
      <mass value="1" />
      <origin xyz="0 0 0.3" />
      <inertia ixx="1.0" ixy="0.0" ixz="0.0"
        iyy="1.0" iyz="0.0" izz="1.0" />
   </inertial>
    <visual>
      <origin xyz="0 0 0.0" rpy="0 0 0"/>
      <geometry>
        <mesh filename="package://veggie_urdf/meshes/Visuals/battery.stl"/>
      </geometry>
        <material name="red"/>
    </visual>
    <collision>
      <origin xyz="0 0 0.0" rpy="0 0 0"/>
      <geometry>
        <mesh filename="package://veggie_urdf/meshes/Collisions/battery.stl"/>
      </geometry>
    </collision>
  </link>

 <joint name="fixed_joint_6" type="fixed">
    <parent link="sixth_link"/>
    <child link="battery"/>
    <origin xyz="0 0 0" rpy="0 0 0"/>
   </joint>

  <link name="kinect">
  <inertial>
      <mass value="0.1" />
      <origin xyz="0 0 0.5" />
      <inertia ixx="1.0" ixy="0.0" ixz="0.0"
        iyy="1.0" iyz="0.0" izz="1.0" />
   </inertial>
  <visual>
   <origin rpy="0 0 0" xyz="0 0 0"/>
    <geometry> 
      <mesh filename="package://veggie_urdf/meshes/Visuals/kinect.dae"/>
    </geometry>
  </visual>
  <collision>
      <origin xyz="0 0 0.0" rpy="0 0 0"/>
      <geometry>
        <mesh filename="package://veggie_urdf/meshes/Collisions/kinect.stl"/>
      </geometry>
    </collision>
  </link>

<joint name="fixed_joint_kinect" type="fixed">
    <parent link="base_link"/>
    <child link="kinect"/>
    <origin xyz="0.05995 0 0.555" rpy="0 0 1.57"/>
   </joint>

  <joint name="imu_joint" type="fixed">
    <parent link="base_link"/>
    <child link="imu_link"/>
    <origin xyz="-0.025 0.04 0.1725" rpy="0 0 3.14"/>
  </joint>

  <link name="imu_link"/>

   <joint name="wheel_left_joint" type="continuous">
    <parent link="base_link"/>
    <child link="wheel_left"/>
    <origin xyz="0.0 0.114 0.03" rpy="0 0 0"/>
    <axis xyz="0 1 0"/>
  </joint>

  <link name="wheel_left">
    <inertial>
      <mass value="0.1" />
      <origin xyz="0 0 0" />
      <inertia ixx="1.0" ixy="0.0" ixz="0.0"
        iyy="1.0" iyz="0.0" izz="1.0" />
   </inertial>
    <visual>
      <origin xyz="0 0 0" rpy="-1.57 0 0"/>
      <geometry>
        <mesh filename="package://veggie_urdf/meshes/Visuals/wheel_left.stl"/>
      </geometry>
       <material name="grey"/>
    </visual>
  <collision>
      <origin xyz="0 0 0.0" rpy="-1.57 0 0"/>
      <geometry>
        <mesh filename="package://veggie_urdf/meshes/Collisions/wheel_left.stl"/>
      </geometry>
    </collision>
  </link>

  <joint name="wheel_right_joint" type="continuous">
    <parent link="base_link"/>
    <child link="wheel_right"/>
    <origin xyz="0.0 -0.114 0.03" rpy="0 0 0"/>
    <axis xyz="0 1 0"/>
  </joint>

  <link name="wheel_right">
   <inertial>
      <mass value="0.1" />
      <origin xyz="0 0 0" />
      <inertia ixx="1.0" ixy="0.0" ixz="0.0"
        iyy="1.0" iyz="0.0" izz="1.0" />
   </inertial> 
   <visual>
      <origin xyz="0 0 0" rpy="1.57 0 0"/>
      <geometry>
        <mesh filename="package://veggie_urdf/meshes/Visuals/wheel_right.stl"/>
      </geometry>
      <material name="grey"/>
    </visual>
    <collision>
      <origin xyz="0 0 0.0" rpy="1.57 0 0"/>
      <geometry>
        <mesh filename="package://veggie_urdf/meshes/Collisions/wheel_right.stl"/>
      </geometry>
    </collision>
  </link>



</robot>
